Workbook

Sheet Competencias_actuales
B1: Competencias actuales del laboratorio
A2: =VALUE(LEFT(F4,FIND(" - ",F4)-1)) -> 797
D3: Nombre del Curso | F3: =IFERROR(__xludf.DUMMYFUNCTION("VLOOKUP(A2,IMPORTRANGE(""1j2lHEvOoZ_EPY086Qt7f7AFaZGVfiYKJxXlsnNfWCA0"", ""Listado Cursos!$A$2:$H$100""),2,FALSE)"),"Seminario de Sistemas 1") -> Seminario de Sistemas 1
D4: Código del Curso | F4: 797 - Seminario de Sistemas 1
D5: Semestre | F5: =IFERROR(__xludf.DUMMYFUNCTION("VLOOKUP(A2,IMPORTRANGE(""1j2lHEvOoZ_EPY086Qt7f7AFaZGVfiYKJxXlsnNfWCA0"", ""Listado Cursos!A:G""),4,FALSE)"),8.0) -> 8
D6: Área de Conocimiento | F6: =IFERROR(__xludf.DUMMYFUNCTION("VLOOKUP(A2,IMPORTRANGE(""1j2lHEvOoZ_EPY086Qt7f7AFaZGVfiYKJxXlsnNfWCA0"", ""Listado Cursos!A:G""),6,FALSE)"),"Sistemas") -> Sistemas
D7: Cantidad de Creditos | F7: =IFERROR(__xludf.DUMMYFUNCTION("VLOOKUP(A2,IMPORTRANGE(""1j2lHEvOoZ_EPY086Qt7f7AFaZGVfiYKJxXlsnNfWCA0"", ""Listado Cursos!A:G""),3,FALSE)"),5.0) -> 5
D8: Horas de aprendizaje | F8: 4
B11: Descripción del Contexto
B13: Que cursos prerrequisito tiene | F13: Cursos que lleva en el mismo semestre | J13: Qué cursos posteriores dependen de este
B14: No. | C14: Codigo | D14: Nombre | F14: No. | G14: Codigo | H14: Nombre | J14: No. | K14: Codigo | L14: Nombre
B15: 1 | C15: =IFERROR(__xludf.DUMMYFUNCTION("ARRAYFORMULA(TRANSPOSE(SPLIT(FILTER(IMPORTRANGE(""1j2lHEvOoZ_EPY086Qt7f7AFaZGVfiYKJxXlsnNfWCA0"", ""Listado Cursos!E:E""), IMPORTRANGE(""1j2lHEvOoZ_EPY086Qt7f7AFaZGVfiYKJxXlsnNfWCA0"", ""Listado Cursos!A:A"")=A2), "","")))"),281.0) -> 281 | D15: =IFERROR(__xludf.DUMMYFUNCTION("IF(C15="""","""",VLOOKUP(C15,IMPORTRANGE(""1j2lHEvOoZ_EPY086Qt7f7AFaZGVfiYKJxXlsnNfWCA0"", ""Listado Cursos!A:B""),2,FALSE))"),"Sistemas Operativos 1") -> Sistemas Operativos 1 | F15: 1 | G15: =IFERROR(__xludf.DUMMYFUNCTION("FILTER(IMPORTRANGE(""1j2lHEvOoZ_EPY086Qt7f7AFaZGVfiYKJxXlsnNfWCA0"", ""Listado Cursos!A:B""),IMPORTRANGE(""1j2lHEvOoZ_EPY086Qt7f7AFaZGVfiYKJxXlsnNfWCA0"", ""Listado Cursos!D:D"")=F5,IMPORTRANGE(""1j2lHEvOoZ_EPY086Qt7f7AFaZGVfiYKJxXlsnNfWCA0"", ""Listado C"&"ursos!A:A"")<>150)"),285.0) -> 285 | H15: =IFERROR(__xludf.DUMMYFUNCTION("""COMPUTED_VALUE"""),"Sistemas Operativos 2") -> Sistemas Operativos 2 | J15: 1 | K15: =IFERROR(__xludf.DUMMYFUNCTION("FILTER(IMPORTRANGE(""1j2lHEvOoZ_EPY086Qt7f7AFaZGVfiYKJxXlsnNfWCA0"", ""Listado Cursos!A:B""), ISNUMBER(SEARCH(A2, IMPORTRANGE(""1j2lHEvOoZ_EPY086Qt7f7AFaZGVfiYKJxXlsnNfWCA0"", ""Listado Cursos!E:E""))))"),798.0) -> 798 | L15: =IFERROR(__xludf.DUMMYFUNCTION("""COMPUTED_VALUE"""),"Seminario de Sistemas 2") -> Seminario de Sistemas 2
B16: 2 | C16: =IFERROR(__xludf.DUMMYFUNCTION("""COMPUTED_VALUE"""),724.0) -> 724 | D16: =IFERROR(__xludf.DUMMYFUNCTION("IF(C16="""","""",VLOOKUP(C16,IMPORTRANGE(""1j2lHEvOoZ_EPY086Qt7f7AFaZGVfiYKJxXlsnNfWCA0"", ""Listado Cursos!A:B""),2,FALSE))"),"Teoría de Sistemas 2") -> Teoría de Sistemas 2 | F16: 2 | G16: =IFERROR(__xludf.DUMMYFUNCTION("""COMPUTED_VALUE"""),975.0) -> 975 | H16: =IFERROR(__xludf.DUMMYFUNCTION("""COMPUTED_VALUE"""),"Redes de Computadoras 2") -> Redes de Computadoras 2 | J16: 2
B17: 3 | C17: =IFERROR(__xludf.DUMMYFUNCTION("""COMPUTED_VALUE"""),774.0) -> 774 | D17: =IFERROR(__xludf.DUMMYFUNCTION("IF(C17="""","""",VLOOKUP(C17,IMPORTRANGE(""1j2lHEvOoZ_EPY086Qt7f7AFaZGVfiYKJxXlsnNfWCA0"", ""Listado Cursos!A:B""),2,FALSE))"),"Sistemas de Bases de Datos 1") -> Sistemas de Bases de Datos 1 | F17: 3 | G17: =IFERROR(__xludf.DUMMYFUNCTION("""COMPUTED_VALUE"""),775.0) -> 775 | H17: =IFERROR(__xludf.DUMMYFUNCTION("""COMPUTED_VALUE"""),"Sistemas de Bases de Datos 2") -> Sistemas de Bases de Datos 2 | J17: 3
B18: 4 | D18: =IFERROR(__xludf.DUMMYFUNCTION("IF(C18="""","""",VLOOKUP(C18,IMPORTRANGE(""1j2lHEvOoZ_EPY086Qt7f7AFaZGVfiYKJxXlsnNfWCA0"", ""Listado Cursos!A:B""),2,FALSE))"),"") | F18: 4 | G18: =IFERROR(__xludf.DUMMYFUNCTION("""COMPUTED_VALUE"""),283.0) -> 283 | H18: =IFERROR(__xludf.DUMMYFUNCTION("""COMPUTED_VALUE"""),"Análisis y Diseño de Sistemas 1") -> Análisis y Diseño de Sistemas 1 | J18: 4
B19: 5 | D19: =IFERROR(__xludf.DUMMYFUNCTION("IF(C19="""","""",VLOOKUP(C19,IMPORTRANGE(""1j2lHEvOoZ_EPY086Qt7f7AFaZGVfiYKJxXlsnNfWCA0"", ""Listado Cursos!A:B""),2,FALSE))"),"") | F19: 5 | G19: =IFERROR(__xludf.DUMMYFUNCTION("""COMPUTED_VALUE"""),797.0) -> 797 | H19: =IFERROR(__xludf.DUMMYFUNCTION("""COMPUTED_VALUE"""),"Seminario de Sistemas 1") -> Seminario de Sistemas 1 | J19: 5
B20: 6 | D20: =IFERROR(__xludf.DUMMYFUNCTION("IF(C20="""","""",VLOOKUP(C20,IMPORTRANGE(""1j2lHEvOoZ_EPY086Qt7f7AFaZGVfiYKJxXlsnNfWCA0"", ""Listado Cursos!A:B""),2,FALSE))"),"") | F20: 6 | G20: =IFERROR(__xludf.DUMMYFUNCTION("""COMPUTED_VALUE"""),700.0) -> 700 | H20: =IFERROR(__xludf.DUMMYFUNCTION("""COMPUTED_VALUE"""),"Ingeniería Económica 1") -> Ingeniería Económica 1 | J20: 6
B21: 7 | D21: =IFERROR(__xludf.DUMMYFUNCTION("IF(C21="""","""",VLOOKUP(C21,IMPORTRANGE(""1j2lHEvOoZ_EPY086Qt7f7AFaZGVfiYKJxXlsnNfWCA0"", ""Listado Cursos!A:B""),2,FALSE))"),"") | F21: 7 | J21: 7
B22: 8 | D22: =IFERROR(__xludf.DUMMYFUNCTION("IF(C22="""","""",VLOOKUP(C22,IMPORTRANGE(""1j2lHEvOoZ_EPY086Qt7f7AFaZGVfiYKJxXlsnNfWCA0"", ""Listado Cursos!A:B""),2,FALSE))"),"") | F22: 8 | J22: 8
B23: 9 | D23: =IFERROR(__xludf.DUMMYFUNCTION("IF(C23="""","""",VLOOKUP(C23,IMPORTRANGE(""1j2lHEvOoZ_EPY086Qt7f7AFaZGVfiYKJxXlsnNfWCA0"", ""Listado Cursos!A:B""),2,FALSE))"),"") | F23: 9 | J23: 9
B24: 10 | D24: =IFERROR(__xludf.DUMMYFUNCTION("IF(C24="""","""",VLOOKUP(C24,IMPORTRANGE(""1j2lHEvOoZ_EPY086Qt7f7AFaZGVfiYKJxXlsnNfWCA0"", ""Listado Cursos!A:B""),2,FALSE))"),"") | F24: 10 | J24: 10
B25: 11 | D25: =IFERROR(__xludf.DUMMYFUNCTION("IF(C25="""","""",VLOOKUP(C25,IMPORTRANGE(""1j2lHEvOoZ_EPY086Qt7f7AFaZGVfiYKJxXlsnNfWCA0"", ""Listado Cursos!A:B""),2,FALSE))"),"") | F25: 11 | J25: 11
B26: 12 | D26: =IFERROR(__xludf.DUMMYFUNCTION("IF(C26="""","""",VLOOKUP(C26,IMPORTRANGE(""1j2lHEvOoZ_EPY086Qt7f7AFaZGVfiYKJxXlsnNfWCA0"", ""Listado Cursos!A:B""),2,FALSE))"),"") | F26: 12 | J26: 12
B27: 13 | D27: =IFERROR(__xludf.DUMMYFUNCTION("IF(C27="""","""",VLOOKUP(C27,IMPORTRANGE(""1j2lHEvOoZ_EPY086Qt7f7AFaZGVfiYKJxXlsnNfWCA0"", ""Listado Cursos!A:B""),2,FALSE))"),"") | F27: 13 | J27: 13
B28: 14 | D28: =IFERROR(__xludf.DUMMYFUNCTION("IF(C28="""","""",VLOOKUP(C28,IMPORTRANGE(""1j2lHEvOoZ_EPY086Qt7f7AFaZGVfiYKJxXlsnNfWCA0"", ""Listado Cursos!A:B""),2,FALSE))"),"") | F28: 14 | J28: 14
B31: Competencias Actuales
B33: No. | C33: Tipo | D33: Competencia | L33: Nivel de la Taxonomina
B34: =IFERROR(__xludf.DUMMYFUNCTION("FILTER(METADA!D2:D17, ISEVEN(ROW(METADA!D2:D17)))"),1.0) -> 1 | C34: =IFERROR(__xludf.DUMMYFUNCTION("FILTER(METADA!E2:E17, ISEVEN(ROW(METADA!E2:E17)))"),"Especifica") -> Especifica | D34: =IFERROR(__xludf.DUMMYFUNCTION("FILTER(METADA!E2:E17, ISODD(ROW(METADA!E2:E17)))"),"Explica el concepto de Cloud Computing, sus modelos de servicio y las ventajas y limitaciones de distintos proveedores Cloud mediante ejemplos cotidianos, casos de uso empresarial y comparativas para el desarrollo de infraestructuras escalables y rentab"&"les. ") -> Explica el concepto de Cloud Computing, sus modelos de servicio y las ventajas y limitaciones de distintos proveedores Cloud mediante ejemplos cotidianos, casos de uso empresarial y comparativas para el desarrollo de infraestructuras escalables y rentables. | L34: =IFERROR(__xludf.DUMMYFUNCTION("FILTER(METADA!L2:L17, ISEVEN(ROW(METADA!L2:L17)))"),"Comprender") -> Comprender
B35: =IFERROR(__xludf.DUMMYFUNCTION("""COMPUTED_VALUE"""),2.0) -> 2 | C35: =IFERROR(__xludf.DUMMYFUNCTION("""COMPUTED_VALUE"""),"Especifica") -> Especifica | D35: =IFERROR(__xludf.DUMMYFUNCTION("""COMPUTED_VALUE"""),"Implementa servicios básicos de Cloud utilizando Amazon EC2, Amazon RDS, Amazon S3, Azure Virtual Machines, Azure SQL, Azure Blob Storage, Azure App Services y Azure Logic Apps para desplegar aplicaciones básicas, considerando la configuración de redes, s"&"eguridad y escalabilidad. ") -> Implementa servicios básicos de Cloud utilizando Amazon EC2, Amazon RDS, Amazon S3, Azure Virtual Machines, Azure SQL, Azure Blob Storage, Azure App Services y Azure Logic Apps para desplegar aplicaciones básicas, considerando la configuración de redes, seguridad y escalabilidad. | L35: =IFERROR(__xludf.DUMMYFUNCTION("""COMPUTED_VALUE"""),"Aplicar") -> Aplicar
B36: =IFERROR(__xludf.DUMMYFUNCTION("""COMPUTED_VALUE"""),3.0) -> 3 | C36: =IFERROR(__xludf.DUMMYFUNCTION("""COMPUTED_VALUE"""),"Especifica") -> Especifica | D36: =IFERROR(__xludf.DUMMYFUNCTION("""COMPUTED_VALUE"""),"Desarrolla aplicaciones serverless simples utilizando AWS Lambda y Azure Functions para procesar eventos y ejecutar la lógica de los negocios ") -> Desarrolla aplicaciones serverless simples utilizando AWS Lambda y Azure Functions para procesar eventos y ejecutar la lógica de los negocios | L36: =IFERROR(__xludf.DUMMYFUNCTION("""COMPUTED_VALUE"""),"Aplicar") -> Aplicar
B37: =IFERROR(__xludf.DUMMYFUNCTION("""COMPUTED_VALUE"""),4.0) -> 4 | C37: =IFERROR(__xludf.DUMMYFUNCTION("""COMPUTED_VALUE"""),"Especifica") -> Especifica | D37: =IFERROR(__xludf.DUMMYFUNCTION("""COMPUTED_VALUE"""),"Implementa servicios de inteligencia artificial utilizando IA de AWS y Azure Cognitive Services para resolver problemas de lenguaje natrual, análisis de imagenes o chabots. ") -> Implementa servicios de inteligencia artificial utilizando IA de AWS y Azure Cognitive Services para resolver problemas de lenguaje natrual, análisis de imagenes o chabots. | L37: =IFERROR(__xludf.DUMMYFUNCTION("""COMPUTED_VALUE"""),"Crear") -> Crear
B38: =IFERROR(__xludf.DUMMYFUNCTION("""COMPUTED_VALUE"""),5.0) -> 5 | C38: =IFERROR(__xludf.DUMMYFUNCTION("""COMPUTED_VALUE"""),"Especifica") -> Especifica | D38: =IFERROR(__xludf.DUMMYFUNCTION("""COMPUTED_VALUE"""),"Desarrolla aplicaciones low-code utilizando Power Automate y Power appas para integrar sistemas, flujos de trabajo y datos. ") -> Desarrolla aplicaciones low-code utilizando Power Automate y Power appas para integrar sistemas, flujos de trabajo y datos. | L38: =IFERROR(__xludf.DUMMYFUNCTION("""COMPUTED_VALUE"""),"Aplicar") -> Aplicar
B39: =IFERROR(__xludf.DUMMYFUNCTION("""COMPUTED_VALUE"""),6.0) -> 6 | C39: =IFERROR(__xludf.DUMMYFUNCTION("""COMPUTED_VALUE"""),"Especifica") -> Especifica | D39: =IFERROR(__xludf.DUMMYFUNCTION("""COMPUTED_VALUE"""),"Empaqueta aplicaciones en contenedores utilizando Docker para garantizar portabilidad y consistencia entre entornos de desarrollo, pruebas y producción. ") -> Empaqueta aplicaciones en contenedores utilizando Docker para garantizar portabilidad y consistencia entre entornos de desarrollo, pruebas y producción. | L39: =IFERROR(__xludf.DUMMYFUNCTION("""COMPUTED_VALUE"""),"Aplicar") -> Aplicar
B40: =IFERROR(__xludf.DUMMYFUNCTION("""COMPUTED_VALUE"""),7.0) -> 7 | C40: =IFERROR(__xludf.DUMMYFUNCTION("""COMPUTED_VALUE"""),"General") -> General | D40: =IFERROR(__xludf.DUMMYFUNCTION("""COMPUTED_VALUE"""),"Aplica principios básicos de ingeniería a través de conceptos de Cloud Computing para el desarrollo de aplicaciones básicas ") -> Aplica principios básicos de ingeniería a través de conceptos de Cloud Computing para el desarrollo de aplicaciones básicas | L40: =IFERROR(__xludf.DUMMYFUNCTION("""COMPUTED_VALUE"""),"Aplicar") -> Aplicar

Sheet Referentes Internacionales
B1: Identificación de referentes internacionales
B3: Nombre del Curso | C3: =Competencias_actuales!F3 -> Seminario de Sistemas 1
B4: Codigo del Curso | C4: 797
B6: 1. Universidad Refente
B7: Analiza cursos similares en universidades internacionales reconocidas (como MIT, Stanford o ETH Zurich) para comparar temas, herramientas y competencias. Esto permite identificar buenas prácticas y alinear el laboratorio con tendencias globales en educación tecnológica.
B9: Nombre de la Universidad | C9: Columbia University
B10: Nombre del Curso | C10: W4153 Cloud Computing
B11: Fuente de Información | C11: https://donald-f-ferguson.github.io/W4153-Cloud-Computing-Base/ https://doc.sis.columbia.edu/subj/COMS/W4153-20243-001
B13: Temas relacionados al laboratorio que se imparte
B14: Infrastructure-as-a-Service, Container-as-a-Service, Platform-as-a-Service, Function-as-a-Service, API-as-a-Service (OpenAPI), Software-as-a-Service, Bases de datos en la nube y almacenamiento en la nube, Multi-tenant applications, Microservices, REST, GraphQL, OpenID, OAuth2, cloud identity and access management, Gestión de nube y aplicaciones, monitoreo y operaciones, Continuous integration/continuous delivery, Service, application and infrastructure integration and orchestration, Architecture, software and cloud design patterns and best practices.
B17: Herramientas utilizadas relacionados al laboratorio que se imparte
B18: AWS, Microsoft Azure Services y Google Cloud Platform Services
B21: Competencia(s) relacionada(s) al laboratorio que se imparte
B22: Habilidades de ingeniería de software + aplicación práctica de servicios en la nube, Proyectos colaborativos con herramientas reales de nube, Uso de nubes reales
B26: 2. Estandar Internacional
B27: Se identifican estándares internacionales relevantes (como ABET, CDIO o IEEE/ACM) para verificar si el laboratorio cumple con criterios de calidad educativa, competencias clave y buenas prácticas recomendadas a nivel global.
B29: Nombre del Estandar | C29: ABET
B30: Sección , Capitulo , etc, | C30: ABET SECCION 3
B31: Funte de Información | C31: https://bulletin.columbia.edu/columbia-engineering/student-handbook/Student_Handbook_2024-2025.pdf (PAGINA 4)
B33: Contenidos relacionados al laboratorio que se imparte
B34: Seguridad de nube, identity & access management (OpenID/OAuth2) Plataforma como servicio, función como servicio, SaaS (y más temas en semanas posteriores)
B37: Nombre del Estandar | C37: ABET
B38: Sección , Capitulo , etc, | C38: ABET SECCION 3
B39: Funte de Información | C39: https://bulletin.columbia.edu/columbia-engineering/student-handbook/Student_Handbook_2024-2025.pdf (PAGINA 4)
B41: Contenidos relacionados al laboratorio que se imparte
B42: Introducción, conceptos centrales, microservicios, aplicaciones full-stack Virtualización, IaaS, REST, OpenAPI, API gateway Contenedores, Container-as-a-Service, GraphQL, composición de servicios, datos en la nube y almacenamiento

Sheet TCO_vrs_Referentes
B1: Comparación con referentes internacionales
A2: =C4&" - "&C3 -> 797 - Seminario de Sistemas 1
B3: Nombre del Curso | C3: =Competencias_actuales!F3 -> Seminario de Sistemas 1
B4: Codigo del Curso | C4: =Competencias_actuales!A2 -> 797
B6: Laboratorio Actual | F6: Universidad Referente | G6: Estandar Referente
B7: Competencia | C7: Unidad | D7: Tema | E7: SubTema | F7: Presente en el referente (Sí/No) | G7: Presente en el referente (Sí/No)
B8: =IFERROR(__xludf.DUMMYFUNCTION("QUERY(IMPORTRANGE(VLOOKUP(A2,METADA!A:B,2,FALSE), ""Diseño Curricular!B4:E500""), )"),"Explica el concepto de Cloud Computing, sus modelos de servicio y las ventajas y limitaciones de distintos proveedores Cloud mediante ejemplos cotidianos, casos de uso empresarial y comparativas para el desarrollo de infraestructuras escalables y rentab"&"les. ") -> Explica el concepto de Cloud Computing, sus modelos de servicio y las ventajas y limitaciones de distintos proveedores Cloud mediante ejemplos cotidianos, casos de uso empresarial y comparativas para el desarrollo de infraestructuras escalables y rentables. | C8: =IFERROR(__xludf.DUMMYFUNCTION("""COMPUTED_VALUE"""),"1 - Conceptos Fundamentales de la Computación en la Nube") -> 1 - Conceptos Fundamentales de la Computación en la Nube | D8: =IFERROR(__xludf.DUMMYFUNCTION("""COMPUTED_VALUE"""),"Introducción a Cloud Computing.") -> Introducción a Cloud Computing. | E8: =IFERROR(__xludf.DUMMYFUNCTION("""COMPUTED_VALUE"""),"Definición y beneficios.") -> Definición y beneficios. | F8: SI | G8: Si
B9: =IFERROR(__xludf.DUMMYFUNCTION("""COMPUTED_VALUE"""),"Explica el concepto de Cloud Computing, sus modelos de servicio y las ventajas y limitaciones de distintos proveedores Cloud mediante ejemplos cotidianos, casos de uso empresarial y comparativas para el desarrollo de infraestructuras escalables y rentab"&"les. ") -> Explica el concepto de Cloud Computing, sus modelos de servicio y las ventajas y limitaciones de distintos proveedores Cloud mediante ejemplos cotidianos, casos de uso empresarial y comparativas para el desarrollo de infraestructuras escalables y rentables. | C9: =IFERROR(__xludf.DUMMYFUNCTION("""COMPUTED_VALUE"""),"1 - Conceptos Fundamentales de la Computación en la Nube") -> 1 - Conceptos Fundamentales de la Computación en la Nube | D9: =IFERROR(__xludf.DUMMYFUNCTION("""COMPUTED_VALUE"""),"Introducción a Cloud Computing.") -> Introducción a Cloud Computing. | E9: =IFERROR(__xludf.DUMMYFUNCTION("""COMPUTED_VALUE"""),"Modelos de servicios (IaaS, PaaS, SaaS).") -> Modelos de servicios (IaaS, PaaS, SaaS). | F9: Sí | G9: Sí
B10: =IFERROR(__xludf.DUMMYFUNCTION("""COMPUTED_VALUE"""),"Explica el concepto de Cloud Computing, sus modelos de servicio y las ventajas y limitaciones de distintos proveedores Cloud mediante ejemplos cotidianos, casos de uso empresarial y comparativas para el desarrollo de infraestructuras escalables y rentab"&"les. ") -> Explica el concepto de Cloud Computing, sus modelos de servicio y las ventajas y limitaciones de distintos proveedores Cloud mediante ejemplos cotidianos, casos de uso empresarial y comparativas para el desarrollo de infraestructuras escalables y rentables. | C10: =IFERROR(__xludf.DUMMYFUNCTION("""COMPUTED_VALUE"""),"1 - Conceptos Fundamentales de la Computación en la Nube") -> 1 - Conceptos Fundamentales de la Computación en la Nube | D10: =IFERROR(__xludf.DUMMYFUNCTION("""COMPUTED_VALUE"""),"Introducción a Cloud Computing.") -> Introducción a Cloud Computing. | E10: =IFERROR(__xludf.DUMMYFUNCTION("""COMPUTED_VALUE"""),"Introducción a los principales proveedores: Google Cloud y Microsoft Azure.") -> Introducción a los principales proveedores: Google Cloud y Microsoft Azure. | F10: Sí | G10: Sí
B11: =IFERROR(__xludf.DUMMYFUNCTION("""COMPUTED_VALUE"""),"Explica el concepto de Cloud Computing, sus modelos de servicio y las ventajas y limitaciones de distintos proveedores Cloud mediante ejemplos cotidianos, casos de uso empresarial y comparativas para el desarrollo de infraestructuras escalables y rentab"&"les. ") -> Explica el concepto de Cloud Computing, sus modelos de servicio y las ventajas y limitaciones de distintos proveedores Cloud mediante ejemplos cotidianos, casos de uso empresarial y comparativas para el desarrollo de infraestructuras escalables y rentables. | C11: =IFERROR(__xludf.DUMMYFUNCTION("""COMPUTED_VALUE"""),"2 - Servicios clave de proveedores Cloud") -> 2 - Servicios clave de proveedores Cloud | D11: =IFERROR(__xludf.DUMMYFUNCTION("""COMPUTED_VALUE"""),"Servicios clave de Google Cloud") -> Servicios clave de Google Cloud | E11: =IFERROR(__xludf.DUMMYFUNCTION("""COMPUTED_VALUE"""),"Servicios de cómputo, almacenamiento y red en Google Cloud.") -> Servicios de cómputo, almacenamiento y red en Google Cloud. | F11: Sí | G11: Sí
B12: =IFERROR(__xludf.DUMMYFUNCTION("""COMPUTED_VALUE"""),"Explica el concepto de Cloud Computing, sus modelos de servicio y las ventajas y limitaciones de distintos proveedores Cloud mediante ejemplos cotidianos, casos de uso empresarial y comparativas para el desarrollo de infraestructuras escalables y rentab"&"les. ") -> Explica el concepto de Cloud Computing, sus modelos de servicio y las ventajas y limitaciones de distintos proveedores Cloud mediante ejemplos cotidianos, casos de uso empresarial y comparativas para el desarrollo de infraestructuras escalables y rentables. | C12: =IFERROR(__xludf.DUMMYFUNCTION("""COMPUTED_VALUE"""),"2 - Servicios clave de proveedores Cloud") -> 2 - Servicios clave de proveedores Cloud | D12: =IFERROR(__xludf.DUMMYFUNCTION("""COMPUTED_VALUE"""),"Servicios clave de Google Cloud") -> Servicios clave de Google Cloud | E12: =IFERROR(__xludf.DUMMYFUNCTION("""COMPUTED_VALUE"""),"Casos de uso de Google Cloud.") -> Casos de uso de Google Cloud. | F12: Sí | G12: Sí
B13: =IFERROR(__xludf.DUMMYFUNCTION("""COMPUTED_VALUE"""),"Explica el concepto de Cloud Computing, sus modelos de servicio y las ventajas y limitaciones de distintos proveedores Cloud mediante ejemplos cotidianos, casos de uso empresarial y comparativas para el desarrollo de infraestructuras escalables y rentab"&"les. ") -> Explica el concepto de Cloud Computing, sus modelos de servicio y las ventajas y limitaciones de distintos proveedores Cloud mediante ejemplos cotidianos, casos de uso empresarial y comparativas para el desarrollo de infraestructuras escalables y rentables. | C13: =IFERROR(__xludf.DUMMYFUNCTION("""COMPUTED_VALUE"""),"2 - Servicios clave de proveedores Cloud") -> 2 - Servicios clave de proveedores Cloud | D13: =IFERROR(__xludf.DUMMYFUNCTION("""COMPUTED_VALUE"""),"Servicios clave de Microsoft Azure.") -> Servicios clave de Microsoft Azure. | E13: =IFERROR(__xludf.DUMMYFUNCTION("""COMPUTED_VALUE"""),"Servicios de cómputo, almacenamiento y red en Azure.") -> Servicios de cómputo, almacenamiento y red en Azure. | G13: Sí
B14: =IFERROR(__xludf.DUMMYFUNCTION("""COMPUTED_VALUE"""),"Explica el concepto de Cloud Computing, sus modelos de servicio y las ventajas y limitaciones de distintos proveedores Cloud mediante ejemplos cotidianos, casos de uso empresarial y comparativas para el desarrollo de infraestructuras escalables y rentab"&"les. ") -> Explica el concepto de Cloud Computing, sus modelos de servicio y las ventajas y limitaciones de distintos proveedores Cloud mediante ejemplos cotidianos, casos de uso empresarial y comparativas para el desarrollo de infraestructuras escalables y rentables. | C14: =IFERROR(__xludf.DUMMYFUNCTION("""COMPUTED_VALUE"""),"2 - Servicios clave de proveedores Cloud") -> 2 - Servicios clave de proveedores Cloud | D14: =IFERROR(__xludf.DUMMYFUNCTION("""COMPUTED_VALUE"""),"Servicios clave de Microsoft Azure.") -> Servicios clave de Microsoft Azure. | E14: =IFERROR(__xludf.DUMMYFUNCTION("""COMPUTED_VALUE"""),"Casos de uso de Azure.") -> Casos de uso de Azure. | F14: Sí | G14: Sí
B15: =IFERROR(__xludf.DUMMYFUNCTION("""COMPUTED_VALUE"""),"Implementa servicios básicos de Cloud utilizando Amazon EC2, Amazon RDS, Amazon S3, Azure Virtual Machines, Azure SQL, Azure Blob Storage, Azure App Services y Azure Logic Apps para desplegar aplicaciones básicas, considerando la configuración de redes, s"&"eguridad y escalabilidad. ") -> Implementa servicios básicos de Cloud utilizando Amazon EC2, Amazon RDS, Amazon S3, Azure Virtual Machines, Azure SQL, Azure Blob Storage, Azure App Services y Azure Logic Apps para desplegar aplicaciones básicas, considerando la configuración de redes, seguridad y escalabilidad. | C15: =IFERROR(__xludf.DUMMYFUNCTION("""COMPUTED_VALUE"""),"3 - Configuración y Gestión de Identidades y Accesos en Cloud") -> 3 - Configuración y Gestión de Identidades y Accesos en Cloud | D15: =IFERROR(__xludf.DUMMYFUNCTION("""COMPUTED_VALUE"""),"Usuarios y permisos en AWS.") -> Usuarios y permisos en AWS. | E15: =IFERROR(__xludf.DUMMYFUNCTION("""COMPUTED_VALUE"""),"Grupos, Usuarios y Roles: Gestión de accesos y permisos.") -> Grupos, Usuarios y Roles: Gestión de accesos y permisos. | F15: Sí | G15: Sí
B16: =IFERROR(__xludf.DUMMYFUNCTION("""COMPUTED_VALUE"""),"Implementa servicios básicos de Cloud utilizando Amazon EC2, Amazon RDS, Amazon S3, Azure Virtual Machines, Azure SQL, Azure Blob Storage, Azure App Services y Azure Logic Apps para desplegar aplicaciones básicas, considerando la configuración de redes, s"&"eguridad y escalabilidad. ") -> Implementa servicios básicos de Cloud utilizando Amazon EC2, Amazon RDS, Amazon S3, Azure Virtual Machines, Azure SQL, Azure Blob Storage, Azure App Services y Azure Logic Apps para desplegar aplicaciones básicas, considerando la configuración de redes, seguridad y escalabilidad. | C16: =IFERROR(__xludf.DUMMYFUNCTION("""COMPUTED_VALUE"""),"3 - Configuración y Gestión de Identidades y Accesos en Cloud") -> 3 - Configuración y Gestión de Identidades y Accesos en Cloud | D16: =IFERROR(__xludf.DUMMYFUNCTION("""COMPUTED_VALUE"""),"Usuarios y permisos en AWS.") -> Usuarios y permisos en AWS. | E16: =IFERROR(__xludf.DUMMYFUNCTION("""COMPUTED_VALUE"""),"Políticas: Configuración de políticas de seguridad.") -> Políticas: Configuración de políticas de seguridad. | F16: Sí | G16: Sí
B17: =IFERROR(__xludf.DUMMYFUNCTION("""COMPUTED_VALUE"""),"Implementa servicios básicos de Cloud utilizando Amazon EC2, Amazon RDS, Amazon S3, Azure Virtual Machines, Azure SQL, Azure Blob Storage, Azure App Services y Azure Logic Apps para desplegar aplicaciones básicas, considerando la configuración de redes, s"&"eguridad y escalabilidad. ") -> Implementa servicios básicos de Cloud utilizando Amazon EC2, Amazon RDS, Amazon S3, Azure Virtual Machines, Azure SQL, Azure Blob Storage, Azure App Services y Azure Logic Apps para desplegar aplicaciones básicas, considerando la configuración de redes, seguridad y escalabilidad. | C17: =IFERROR(__xludf.DUMMYFUNCTION("""COMPUTED_VALUE"""),"3 - Configuración y Gestión de Identidades y Accesos en Cloud") -> 3 - Configuración y Gestión de Identidades y Accesos en Cloud | D17: =IFERROR(__xludf.DUMMYFUNCTION("""COMPUTED_VALUE"""),"Creación y configuración de instancias.") -> Creación y configuración de instancias. | E17: =IFERROR(__xludf.DUMMYFUNCTION("""COMPUTED_VALUE"""),"Instancias en AWS, Azure y Google Cloud.") -> Instancias en AWS, Azure y Google Cloud. | F17: Sí | G17: Sí
B18: =IFERROR(__xludf.DUMMYFUNCTION("""COMPUTED_VALUE"""),"Implementa servicios básicos de Cloud utilizando Amazon EC2, Amazon RDS, Amazon S3, Azure Virtual Machines, Azure SQL, Azure Blob Storage, Azure App Services y Azure Logic Apps para desplegar aplicaciones básicas, considerando la configuración de redes, s"&"eguridad y escalabilidad. ") -> Implementa servicios básicos de Cloud utilizando Amazon EC2, Amazon RDS, Amazon S3, Azure Virtual Machines, Azure SQL, Azure Blob Storage, Azure App Services y Azure Logic Apps para desplegar aplicaciones básicas, considerando la configuración de redes, seguridad y escalabilidad. | C18: =IFERROR(__xludf.DUMMYFUNCTION("""COMPUTED_VALUE"""),"3 - Configuración y Gestión de Identidades y Accesos en Cloud") -> 3 - Configuración y Gestión de Identidades y Accesos en Cloud | D18: =IFERROR(__xludf.DUMMYFUNCTION("""COMPUTED_VALUE"""),"Creación y configuración de instancias.") -> Creación y configuración de instancias. | E18: =IFERROR(__xludf.DUMMYFUNCTION("""COMPUTED_VALUE"""),"Configuración básica de las instancias.") -> Configuración básica de las instancias. | F18: Sí | G18: Sí
B19: =IFERROR(__xludf.DUMMYFUNCTION("""COMPUTED_VALUE"""),"Implementa servicios básicos de Cloud utilizando Amazon EC2, Amazon RDS, Amazon S3, Azure Virtual Machines, Azure SQL, Azure Blob Storage, Azure App Services y Azure Logic Apps para desplegar aplicaciones básicas, considerando la configuración de redes, s"&"eguridad y escalabilidad. ") -> Implementa servicios básicos de Cloud utilizando Amazon EC2, Amazon RDS, Amazon S3, Azure Virtual Machines, Azure SQL, Azure Blob Storage, Azure App Services y Azure Logic Apps para desplegar aplicaciones básicas, considerando la configuración de redes, seguridad y escalabilidad. | C19: =IFERROR(__xludf.DUMMYFUNCTION("""COMPUTED_VALUE"""),"3 - Configuración y Gestión de Identidades y Accesos en Cloud") -> 3 - Configuración y Gestión de Identidades y Accesos en Cloud | D19: =IFERROR(__xludf.DUMMYFUNCTION("""COMPUTED_VALUE"""),"Amazon EC2.") -> Amazon EC2. | E19: =IFERROR(__xludf.DUMMYFUNCTION("""COMPUTED_VALUE"""),"Security Groups: Configuración de reglas de firewall.") -> Security Groups: Configuración de reglas de firewall. | F19: Sí | G19: Sí
B20: =IFERROR(__xludf.DUMMYFUNCTION("""COMPUTED_VALUE"""),"Implementa servicios básicos de Cloud utilizando Amazon EC2, Amazon RDS, Amazon S3, Azure Virtual Machines, Azure SQL, Azure Blob Storage, Azure App Services y Azure Logic Apps para desplegar aplicaciones básicas, considerando la configuración de redes, s"&"eguridad y escalabilidad. ") -> Implementa servicios básicos de Cloud utilizando Amazon EC2, Amazon RDS, Amazon S3, Azure Virtual Machines, Azure SQL, Azure Blob Storage, Azure App Services y Azure Logic Apps para desplegar aplicaciones básicas, considerando la configuración de redes, seguridad y escalabilidad. | C20: =IFERROR(__xludf.DUMMYFUNCTION("""COMPUTED_VALUE"""),"3 - Configuración y Gestión de Identidades y Accesos en Cloud") -> 3 - Configuración y Gestión de Identidades y Accesos en Cloud | D20: =IFERROR(__xludf.DUMMYFUNCTION("""COMPUTED_VALUE"""),"Amazon EC2.") -> Amazon EC2. | E20: =IFERROR(__xludf.DUMMYFUNCTION("""COMPUTED_VALUE"""),"Key Pairs: Autenticación de instancias.") -> Key Pairs: Autenticación de instancias. | F20: Sí | G20: Sí
B21: =IFERROR(__xludf.DUMMYFUNCTION("""COMPUTED_VALUE"""),"Implementa servicios básicos de Cloud utilizando Amazon EC2, Amazon RDS, Amazon S3, Azure Virtual Machines, Azure SQL, Azure Blob Storage, Azure App Services y Azure Logic Apps para desplegar aplicaciones básicas, considerando la configuración de redes, s"&"eguridad y escalabilidad. ") -> Implementa servicios básicos de Cloud utilizando Amazon EC2, Amazon RDS, Amazon S3, Azure Virtual Machines, Azure SQL, Azure Blob Storage, Azure App Services y Azure Logic Apps para desplegar aplicaciones básicas, considerando la configuración de redes, seguridad y escalabilidad. | C21: =IFERROR(__xludf.DUMMYFUNCTION("""COMPUTED_VALUE"""),"3 - Configuración y Gestión de Identidades y Accesos en Cloud") -> 3 - Configuración y Gestión de Identidades y Accesos en Cloud | D21: =IFERROR(__xludf.DUMMYFUNCTION("""COMPUTED_VALUE"""),"Amazon EC2.") -> Amazon EC2. | E21: =IFERROR(__xludf.DUMMYFUNCTION("""COMPUTED_VALUE"""),"AMI: Imágenes de máquinas Amazon.") -> AMI: Imágenes de máquinas Amazon. | F21: Sí | G21: Sí
B22: =IFERROR(__xludf.DUMMYFUNCTION("""COMPUTED_VALUE"""),"Implementa servicios básicos de Cloud utilizando Amazon EC2, Amazon RDS, Amazon S3, Azure Virtual Machines, Azure SQL, Azure Blob Storage, Azure App Services y Azure Logic Apps para desplegar aplicaciones básicas, considerando la configuración de redes, s"&"eguridad y escalabilidad. ") -> Implementa servicios básicos de Cloud utilizando Amazon EC2, Amazon RDS, Amazon S3, Azure Virtual Machines, Azure SQL, Azure Blob Storage, Azure App Services y Azure Logic Apps para desplegar aplicaciones básicas, considerando la configuración de redes, seguridad y escalabilidad. | C22: =IFERROR(__xludf.DUMMYFUNCTION("""COMPUTED_VALUE"""),"4 - Configuración e Implementación de Máquinas Virtuales en la nube") -> 4 - Configuración e Implementación de Máquinas Virtuales en la nube | D22: =IFERROR(__xludf.DUMMYFUNCTION("""COMPUTED_VALUE"""),"Amazon EC2.") -> Amazon EC2. | E22: =IFERROR(__xludf.DUMMYFUNCTION("""COMPUTED_VALUE"""),"Elastic IP y Elastic Load Balancing.") -> Elastic IP y Elastic Load Balancing. | F22: Sí | G22: Sí
B23: =IFERROR(__xludf.DUMMYFUNCTION("""COMPUTED_VALUE"""),"Implementa servicios básicos de Cloud utilizando Amazon EC2, Amazon RDS, Amazon S3, Azure Virtual Machines, Azure SQL, Azure Blob Storage, Azure App Services y Azure Logic Apps para desplegar aplicaciones básicas, considerando la configuración de redes, s"&"eguridad y escalabilidad. ") -> Implementa servicios básicos de Cloud utilizando Amazon EC2, Amazon RDS, Amazon S3, Azure Virtual Machines, Azure SQL, Azure Blob Storage, Azure App Services y Azure Logic Apps para desplegar aplicaciones básicas, considerando la configuración de redes, seguridad y escalabilidad. | C23: =IFERROR(__xludf.DUMMYFUNCTION("""COMPUTED_VALUE"""),"5 - Configuración e Implementación de Bases de datos en Cloud Computing") -> 5 - Configuración e Implementación de Bases de datos en Cloud Computing | D23: =IFERROR(__xludf.DUMMYFUNCTION("""COMPUTED_VALUE"""),"Bases de datos en AWS y Azure.") -> Bases de datos en AWS y Azure. | E23: =IFERROR(__xludf.DUMMYFUNCTION("""COMPUTED_VALUE"""),"Amazon RDS: Configuración y administración.") -> Amazon RDS: Configuración y administración. | F23: Sí | G23: Sí
B24: =IFERROR(__xludf.DUMMYFUNCTION("""COMPUTED_VALUE"""),"Implementa servicios básicos de Cloud utilizando Amazon EC2, Amazon RDS, Amazon S3, Azure Virtual Machines, Azure SQL, Azure Blob Storage, Azure App Services y Azure Logic Apps para desplegar aplicaciones básicas, considerando la configuración de redes, s"&"eguridad y escalabilidad. ") -> Implementa servicios básicos de Cloud utilizando Amazon EC2, Amazon RDS, Amazon S3, Azure Virtual Machines, Azure SQL, Azure Blob Storage, Azure App Services y Azure Logic Apps para desplegar aplicaciones básicas, considerando la configuración de redes, seguridad y escalabilidad. | C24: =IFERROR(__xludf.DUMMYFUNCTION("""COMPUTED_VALUE"""),"5 - Configuración e Implementación de Bases de datos en Cloud Computing") -> 5 - Configuración e Implementación de Bases de datos en Cloud Computing | D24: =IFERROR(__xludf.DUMMYFUNCTION("""COMPUTED_VALUE"""),"Bases de datos en AWS y Azure.") -> Bases de datos en AWS y Azure. | E24: =IFERROR(__xludf.DUMMYFUNCTION("""COMPUTED_VALUE"""),"Azure SQL: Servicios de bases de datos en Azure.") -> Azure SQL: Servicios de bases de datos en Azure. | F24: Sí | G24: Sí
B25: =IFERROR(__xludf.DUMMYFUNCTION("""COMPUTED_VALUE"""),"Implementa servicios básicos de Cloud utilizando Amazon EC2, Amazon RDS, Amazon S3, Azure Virtual Machines, Azure SQL, Azure Blob Storage, Azure App Services y Azure Logic Apps para desplegar aplicaciones básicas, considerando la configuración de redes, s"&"eguridad y escalabilidad. ") -> Implementa servicios básicos de Cloud utilizando Amazon EC2, Amazon RDS, Amazon S3, Azure Virtual Machines, Azure SQL, Azure Blob Storage, Azure App Services y Azure Logic Apps para desplegar aplicaciones básicas, considerando la configuración de redes, seguridad y escalabilidad. | C25: =IFERROR(__xludf.DUMMYFUNCTION("""COMPUTED_VALUE"""),"6 - Servicios de Almcaenamiento de Objetos en Cloud") -> 6 - Servicios de Almcaenamiento de Objetos en Cloud | D25: =IFERROR(__xludf.DUMMYFUNCTION("""COMPUTED_VALUE"""),"Servicios de almacenamiento.") -> Servicios de almacenamiento. | E25: =IFERROR(__xludf.DUMMYFUNCTION("""COMPUTED_VALUE"""),"Azure Storage: Tipos y usos.") -> Azure Storage: Tipos y usos. | F25: Sí | G25: Sí
B26: =IFERROR(__xludf.DUMMYFUNCTION("""COMPUTED_VALUE"""),"Implementa servicios básicos de Cloud utilizando Amazon EC2, Amazon RDS, Amazon S3, Azure Virtual Machines, Azure SQL, Azure Blob Storage, Azure App Services y Azure Logic Apps para desplegar aplicaciones básicas, considerando la configuración de redes, s"&"eguridad y escalabilidad. ") -> Implementa servicios básicos de Cloud utilizando Amazon EC2, Amazon RDS, Amazon S3, Azure Virtual Machines, Azure SQL, Azure Blob Storage, Azure App Services y Azure Logic Apps para desplegar aplicaciones básicas, considerando la configuración de redes, seguridad y escalabilidad. | C26: =IFERROR(__xludf.DUMMYFUNCTION("""COMPUTED_VALUE"""),"6 - Servicios de Almcaenamiento de Objetos en Cloud") -> 6 - Servicios de Almcaenamiento de Objetos en Cloud | D26: =IFERROR(__xludf.DUMMYFUNCTION("""COMPUTED_VALUE"""),"Servicios de almacenamiento.") -> Servicios de almacenamiento. | E26: =IFERROR(__xludf.DUMMYFUNCTION("""COMPUTED_VALUE"""),"Amazon S3: Almacenamiento de objetos y accesos.") -> Amazon S3: Almacenamiento de objetos y accesos. | F26: Sí | G26: Sí
B27: =IFERROR(__xludf.DUMMYFUNCTION("""COMPUTED_VALUE"""),"Implementa servicios básicos de Cloud utilizando Amazon EC2, Amazon RDS, Amazon S3, Azure Virtual Machines, Azure SQL, Azure Blob Storage, Azure App Services y Azure Logic Apps para desplegar aplicaciones básicas, considerando la configuración de redes, s"&"eguridad y escalabilidad. ") -> Implementa servicios básicos de Cloud utilizando Amazon EC2, Amazon RDS, Amazon S3, Azure Virtual Machines, Azure SQL, Azure Blob Storage, Azure App Services y Azure Logic Apps para desplegar aplicaciones básicas, considerando la configuración de redes, seguridad y escalabilidad. | C27: =IFERROR(__xludf.DUMMYFUNCTION("""COMPUTED_VALUE"""),"6 - Servicios de Almcaenamiento de Objetos en Cloud") -> 6 - Servicios de Almcaenamiento de Objetos en Cloud | D27: =IFERROR(__xludf.DUMMYFUNCTION("""COMPUTED_VALUE"""),"Servicios de almacenamiento.") -> Servicios de almacenamiento. | E27: =IFERROR(__xludf.DUMMYFUNCTION("""COMPUTED_VALUE"""),"Alojamiento de sitios web estáticos en Amazon S3.") -> Alojamiento de sitios web estáticos en Amazon S3. | F27: Sí | G27: Sí
B28: =IFERROR(__xludf.DUMMYFUNCTION("""COMPUTED_VALUE"""),"Desarrolla aplicaciones serverless simples utilizando AWS Lambda y Azure Functions para procesar eventos y ejecutar la lógica de los negocios ") -> Desarrolla aplicaciones serverless simples utilizando AWS Lambda y Azure Functions para procesar eventos y ejecutar la lógica de los negocios | C28: =IFERROR(__xludf.DUMMYFUNCTION("""COMPUTED_VALUE"""),"7 - Configuración de Arquitecturas Serverless") -> 7 - Configuración de Arquitecturas Serverless | D28: =IFERROR(__xludf.DUMMYFUNCTION("""COMPUTED_VALUE"""),"Serverless en AWS y Azure.") -> Serverless en AWS y Azure. | E28: =IFERROR(__xludf.DUMMYFUNCTION("""COMPUTED_VALUE"""),"AWS Lambda: Ejecución de código sin servidores.") -> AWS Lambda: Ejecución de código sin servidores. | F28: Sí | G28: Sí
B29: =IFERROR(__xludf.DUMMYFUNCTION("""COMPUTED_VALUE"""),"Desarrolla aplicaciones serverless simples utilizando AWS Lambda y Azure Functions para procesar eventos y ejecutar la lógica de los negocios ") -> Desarrolla aplicaciones serverless simples utilizando AWS Lambda y Azure Functions para procesar eventos y ejecutar la lógica de los negocios | C29: =IFERROR(__xludf.DUMMYFUNCTION("""COMPUTED_VALUE"""),"7 - Configuración de Arquitecturas Serverless") -> 7 - Configuración de Arquitecturas Serverless | D29: =IFERROR(__xludf.DUMMYFUNCTION("""COMPUTED_VALUE"""),"Serverless en AWS y Azure.") -> Serverless en AWS y Azure. | E29: =IFERROR(__xludf.DUMMYFUNCTION("""COMPUTED_VALUE"""),"Amazon API Gateway: Gestión de APIs.") -> Amazon API Gateway: Gestión de APIs. | F29: Sí | G29: Sí
B30: =IFERROR(__xludf.DUMMYFUNCTION("""COMPUTED_VALUE"""),"Desarrolla aplicaciones serverless simples utilizando AWS Lambda y Azure Functions para procesar eventos y ejecutar la lógica de los negocios ") -> Desarrolla aplicaciones serverless simples utilizando AWS Lambda y Azure Functions para procesar eventos y ejecutar la lógica de los negocios | C30: =IFERROR(__xludf.DUMMYFUNCTION("""COMPUTED_VALUE"""),"7 - Configuración de Arquitecturas Serverless") -> 7 - Configuración de Arquitecturas Serverless | D30: =IFERROR(__xludf.DUMMYFUNCTION("""COMPUTED_VALUE"""),"Serverless en AWS y Azure.") -> Serverless en AWS y Azure. | E30: =IFERROR(__xludf.DUMMYFUNCTION("""COMPUTED_VALUE"""),"Azure Functions: Funciones sin servidor en Azure.") -> Azure Functions: Funciones sin servidor en Azure. | F30: Sí | G30: Sí
B31: =IFERROR(__xludf.DUMMYFUNCTION("""COMPUTED_VALUE"""),"Desarrolla aplicaciones serverless simples utilizando AWS Lambda y Azure Functions para procesar eventos y ejecutar la lógica de los negocios ") -> Desarrolla aplicaciones serverless simples utilizando AWS Lambda y Azure Functions para procesar eventos y ejecutar la lógica de los negocios | C31: =IFERROR(__xludf.DUMMYFUNCTION("""COMPUTED_VALUE"""),"7 - Configuración de Arquitecturas Serverless") -> 7 - Configuración de Arquitecturas Serverless | D31: =IFERROR(__xludf.DUMMYFUNCTION("""COMPUTED_VALUE"""),"Serverless en AWS y Azure.") -> Serverless en AWS y Azure. | E31: =IFERROR(__xludf.DUMMYFUNCTION("""COMPUTED_VALUE"""),"Azure API Management.") -> Azure API Management. | F31: Sí | G31: Sí
B32: =IFERROR(__xludf.DUMMYFUNCTION("""COMPUTED_VALUE"""),"Implementa servicios básicos de Cloud utilizando Amazon EC2, Amazon RDS, Amazon S3, Azure Virtual Machines, Azure SQL, Azure Blob Storage, Azure App Services y Azure Logic Apps para desplegar aplicaciones básicas, considerando la configuración de redes, s"&"eguridad y escalabilidad. ") -> Implementa servicios básicos de Cloud utilizando Amazon EC2, Amazon RDS, Amazon S3, Azure Virtual Machines, Azure SQL, Azure Blob Storage, Azure App Services y Azure Logic Apps para desplegar aplicaciones básicas, considerando la configuración de redes, seguridad y escalabilidad. | C32: =IFERROR(__xludf.DUMMYFUNCTION("""COMPUTED_VALUE"""),"8 - Desarrollo de aplicaciones con Azure") -> 8 - Desarrollo de aplicaciones con Azure | D32: =IFERROR(__xludf.DUMMYFUNCTION("""COMPUTED_VALUE"""),"Plataformas de desarrollo en Azure") -> Plataformas de desarrollo en Azure | E32: =IFERROR(__xludf.DUMMYFUNCTION("""COMPUTED_VALUE"""),"Azure Load Balancer") -> Azure Load Balancer | F32: Sí | G32: Sí
B33: =IFERROR(__xludf.DUMMYFUNCTION("""COMPUTED_VALUE"""),"Implementa servicios básicos de Cloud utilizando Amazon EC2, Amazon RDS, Amazon S3, Azure Virtual Machines, Azure SQL, Azure Blob Storage, Azure App Services y Azure Logic Apps para desplegar aplicaciones básicas, considerando la configuración de redes, s"&"eguridad y escalabilidad. ") -> Implementa servicios básicos de Cloud utilizando Amazon EC2, Amazon RDS, Amazon S3, Azure Virtual Machines, Azure SQL, Azure Blob Storage, Azure App Services y Azure Logic Apps para desplegar aplicaciones básicas, considerando la configuración de redes, seguridad y escalabilidad. | C33: =IFERROR(__xludf.DUMMYFUNCTION("""COMPUTED_VALUE"""),"8 - Desarrollo de aplicaciones con Azure") -> 8 - Desarrollo de aplicaciones con Azure | D33: =IFERROR(__xludf.DUMMYFUNCTION("""COMPUTED_VALUE"""),"Plataformas de desarrollo en Azure") -> Plataformas de desarrollo en Azure | E33: =IFERROR(__xludf.DUMMYFUNCTION("""COMPUTED_VALUE"""),"Azure App Services") -> Azure App Services | F33: Sí | G33: Sí
B34: =IFERROR(__xludf.DUMMYFUNCTION("""COMPUTED_VALUE"""),"Implementa servicios básicos de Cloud utilizando Amazon EC2, Amazon RDS, Amazon S3, Azure Virtual Machines, Azure SQL, Azure Blob Storage, Azure App Services y Azure Logic Apps para desplegar aplicaciones básicas, considerando la configuración de redes, s"&"eguridad y escalabilidad. ") -> Implementa servicios básicos de Cloud utilizando Amazon EC2, Amazon RDS, Amazon S3, Azure Virtual Machines, Azure SQL, Azure Blob Storage, Azure App Services y Azure Logic Apps para desplegar aplicaciones básicas, considerando la configuración de redes, seguridad y escalabilidad. | C34: =IFERROR(__xludf.DUMMYFUNCTION("""COMPUTED_VALUE"""),"8 - Desarrollo de aplicaciones con Azure") -> 8 - Desarrollo de aplicaciones con Azure | D34: =IFERROR(__xludf.DUMMYFUNCTION("""COMPUTED_VALUE"""),"Plataformas de desarrollo en Azure") -> Plataformas de desarrollo en Azure | E34: =IFERROR(__xludf.DUMMYFUNCTION("""COMPUTED_VALUE"""),"Azure Logic Apps") -> Azure Logic Apps | F34: Sí | G34: Sí
B35: =IFERROR(__xludf.DUMMYFUNCTION("""COMPUTED_VALUE"""),"Implementa servicios de inteligencia artificial utilizando IA de AWS y Azure Cognitive Services para resolver problemas de lenguaje natrual, análisis de imagenes o chabots. ") -> Implementa servicios de inteligencia artificial utilizando IA de AWS y Azure Cognitive Services para resolver problemas de lenguaje natrual, análisis de imagenes o chabots. | C35: =IFERROR(__xludf.DUMMYFUNCTION("""COMPUTED_VALUE"""),"9 - Inteligencia Artificial en Cloud Computing") -> 9 - Inteligencia Artificial en Cloud Computing | D35: =IFERROR(__xludf.DUMMYFUNCTION("""COMPUTED_VALUE"""),"Servicios de IA de AWS.") -> Servicios de IA de AWS. | E35: =IFERROR(__xludf.DUMMYFUNCTION("""COMPUTED_VALUE"""),"Amazon Rekognition: Análisis de imágenes.") -> Amazon Rekognition: Análisis de imágenes. | F35: Sí | G35: Sí
B36: =IFERROR(__xludf.DUMMYFUNCTION("""COMPUTED_VALUE"""),"Implementa servicios de inteligencia artificial utilizando IA de AWS y Azure Cognitive Services para resolver problemas de lenguaje natrual, análisis de imagenes o chabots. ") -> Implementa servicios de inteligencia artificial utilizando IA de AWS y Azure Cognitive Services para resolver problemas de lenguaje natrual, análisis de imagenes o chabots. | C36: =IFERROR(__xludf.DUMMYFUNCTION("""COMPUTED_VALUE"""),"9 - Inteligencia Artificial en Cloud Computing") -> 9 - Inteligencia Artificial en Cloud Computing | D36: =IFERROR(__xludf.DUMMYFUNCTION("""COMPUTED_VALUE"""),"Servicios de IA de AWS.") -> Servicios de IA de AWS. | E36: =IFERROR(__xludf.DUMMYFUNCTION("""COMPUTED_VALUE"""),"Amazon Lex: Creación de chatbots.") -> Amazon Lex: Creación de chatbots. | F36: Sí | G36: Sí
B37: =IFERROR(__xludf.DUMMYFUNCTION("""COMPUTED_VALUE"""),"Implementa servicios de inteligencia artificial utilizando IA de AWS y Azure Cognitive Services para resolver problemas de lenguaje natrual, análisis de imagenes o chabots. ") -> Implementa servicios de inteligencia artificial utilizando IA de AWS y Azure Cognitive Services para resolver problemas de lenguaje natrual, análisis de imagenes o chabots. | C37: =IFERROR(__xludf.DUMMYFUNCTION("""COMPUTED_VALUE"""),"9 - Inteligencia Artificial en Cloud Computing") -> 9 - Inteligencia Artificial en Cloud Computing | D37: =IFERROR(__xludf.DUMMYFUNCTION("""COMPUTED_VALUE"""),"Servicios de IA de AWS.") -> Servicios de IA de AWS. | E37: =IFERROR(__xludf.DUMMYFUNCTION("""COMPUTED_VALUE"""),"Amazon Polly: Conversión de texto a voz.") -> Amazon Polly: Conversión de texto a voz. | F37: Sí | G37: Sí
B38: =IFERROR(__xludf.DUMMYFUNCTION("""COMPUTED_VALUE"""),"Implementa servicios de inteligencia artificial utilizando IA de AWS y Azure Cognitive Services para resolver problemas de lenguaje natrual, análisis de imagenes o chabots. ") -> Implementa servicios de inteligencia artificial utilizando IA de AWS y Azure Cognitive Services para resolver problemas de lenguaje natrual, análisis de imagenes o chabots. | C38: =IFERROR(__xludf.DUMMYFUNCTION("""COMPUTED_VALUE"""),"9 - Inteligencia Artificial en Cloud Computing") -> 9 - Inteligencia Artificial en Cloud Computing | D38: =IFERROR(__xludf.DUMMYFUNCTION("""COMPUTED_VALUE"""),"Servicios de IA de AWS.") -> Servicios de IA de AWS. | E38: =IFERROR(__xludf.DUMMYFUNCTION("""COMPUTED_VALUE"""),"Amazon Translate y Cognito: Traducción automática y autenticación.") -> Amazon Translate y Cognito: Traducción automática y autenticación. | F38: No | G38: No
B39: =IFERROR(__xludf.DUMMYFUNCTION("""COMPUTED_VALUE"""),"Implementa servicios de inteligencia artificial utilizando IA de AWS y Azure Cognitive Services para resolver problemas de lenguaje natrual, análisis de imagenes o chabots. ") -> Implementa servicios de inteligencia artificial utilizando IA de AWS y Azure Cognitive Services para resolver problemas de lenguaje natrual, análisis de imagenes o chabots. | C39: =IFERROR(__xludf.DUMMYFUNCTION("""COMPUTED_VALUE"""),"9 - Inteligencia Artificial en Cloud Computing") -> 9 - Inteligencia Artificial en Cloud Computing | D39: =IFERROR(__xludf.DUMMYFUNCTION("""COMPUTED_VALUE"""),"Azure Cognitive Services.") -> Azure Cognitive Services. | E39: =IFERROR(__xludf.DUMMYFUNCTION("""COMPUTED_VALUE"""),"Servicios de visión, lenguaje y toma de decisiones.") -> Servicios de visión, lenguaje y toma de decisiones. | F39: Sí | G39: Sí
B40: =IFERROR(__xludf.DUMMYFUNCTION("""COMPUTED_VALUE"""),"Implementa servicios de inteligencia artificial utilizando IA de AWS y Azure Cognitive Services para resolver problemas de lenguaje natrual, análisis de imagenes o chabots. ") -> Implementa servicios de inteligencia artificial utilizando IA de AWS y Azure Cognitive Services para resolver problemas de lenguaje natrual, análisis de imagenes o chabots. | C40: =IFERROR(__xludf.DUMMYFUNCTION("""COMPUTED_VALUE"""),"9 - Inteligencia Artificial en Cloud Computing") -> 9 - Inteligencia Artificial en Cloud Computing | D40: =IFERROR(__xludf.DUMMYFUNCTION("""COMPUTED_VALUE"""),"Azure Cognitive Services.") -> Azure Cognitive Services. | E40: =IFERROR(__xludf.DUMMYFUNCTION("""COMPUTED_VALUE"""),"Integración en aplicaciones.") -> Integración en aplicaciones. | F40: Sí | G40: Sí
B41: =IFERROR(__xludf.DUMMYFUNCTION("""COMPUTED_VALUE"""),"Desarrolla aplicaciones low-code utilizando Power Automate y Power appas para integrar sistemas, flujos de trabajo y datos. ") -> Desarrolla aplicaciones low-code utilizando Power Automate y Power appas para integrar sistemas, flujos de trabajo y datos. | C41: =IFERROR(__xludf.DUMMYFUNCTION("""COMPUTED_VALUE"""),"10 - Implementación de Plataformas de Microsoft") -> 10 - Implementación de Plataformas de Microsoft | D41: =IFERROR(__xludf.DUMMYFUNCTION("""COMPUTED_VALUE"""),"Microsoft Power Platforms.") -> Microsoft Power Platforms. | E41: =IFERROR(__xludf.DUMMYFUNCTION("""COMPUTED_VALUE"""),"Power Automate: Automatización de flujos de trabajo.") -> Power Automate: Automatización de flujos de trabajo. | F41: No | G41: No
...

Sheet TCO_Lab_Previo
B1: Que se impartio el en Curso Previo el Segundo Semestre 2025
B3: Nombre del Curso | C3: Sistemas de Bases de Datos 1
B4: Codigo del Curso | C4: {=IFERROR(_xlfn.XLOOKUP(TRIM(C3), Competencias_actuales!D15:D1000, Competencias_actuales!C15:C1000), "Código no encontrado")} -> 774 | H4: =C4&" - "&C3 -> 774 - Sistemas de Bases de Datos 1
B6: No | C6: Competencia | D6: Unidad | E6: Tema | F6: Subtema | G6: Mes | H6: Semana
B7: =IFERROR(__xludf.DUMMYFUNCTION("QUERY(IMPORTRANGE(VLOOKUP(H4,METADA!A:B,2,FALSE), ""Diseño Curricular!A4:G500""), )"),1.0) -> 1 | C7: =IFERROR(__xludf.DUMMYFUNCTION("""COMPUTED_VALUE"""),"Administra bases de datos relacionales utilizando herramientas de gestión como Oracle APEX y SQL Developer para mantener la disponibilidad, seguridad y eficiencia de los sistemas de información ") -> Administra bases de datos relacionales utilizando herramientas de gestión como Oracle APEX y SQL Developer para mantener la disponibilidad, seguridad y eficiencia de los sistemas de información | D7: =IFERROR(__xludf.DUMMYFUNCTION("""COMPUTED_VALUE"""),1.0) -> 1 | E7: =IFERROR(__xludf.DUMMYFUNCTION("""COMPUTED_VALUE"""),"Introducción a base de datos relacionales") -> Introducción a base de datos relacionales | F7: =IFERROR(__xludf.DUMMYFUNCTION("""COMPUTED_VALUE"""),"Bases de datos") -> Bases de datos | G7: =IFERROR(__xludf.DUMMYFUNCTION("""COMPUTED_VALUE"""),"Julio") -> Julio | H7: =IFERROR(__xludf.DUMMYFUNCTION("""COMPUTED_VALUE"""),1.0) -> 1
B8: =IFERROR(__xludf.DUMMYFUNCTION("""COMPUTED_VALUE"""),2.0) -> 2 | C8: =IFERROR(__xludf.DUMMYFUNCTION("""COMPUTED_VALUE"""),"Administra bases de datos relacionales utilizando herramientas de gestión como Oracle APEX y SQL Developer para mantener la disponibilidad, seguridad y eficiencia de los sistemas de información ") -> Administra bases de datos relacionales utilizando herramientas de gestión como Oracle APEX y SQL Developer para mantener la disponibilidad, seguridad y eficiencia de los sistemas de información | D8: =IFERROR(__xludf.DUMMYFUNCTION("""COMPUTED_VALUE"""),1.0) -> 1 | E8: =IFERROR(__xludf.DUMMYFUNCTION("""COMPUTED_VALUE"""),"Introducción a base de datos relacionales") -> Introducción a base de datos relacionales | F8: =IFERROR(__xludf.DUMMYFUNCTION("""COMPUTED_VALUE"""),"Tecnología de Base de Datos Relacional") -> Tecnología de Base de Datos Relacional | G8: =IFERROR(__xludf.DUMMYFUNCTION("""COMPUTED_VALUE"""),"Julio") -> Julio | H8: =IFERROR(__xludf.DUMMYFUNCTION("""COMPUTED_VALUE"""),1.0) -> 1
B9: =IFERROR(__xludf.DUMMYFUNCTION("""COMPUTED_VALUE"""),3.0) -> 3 | C9: =IFERROR(__xludf.DUMMYFUNCTION("""COMPUTED_VALUE"""),"Implementa consultas SQL usando gestores de bases de datos relacionales como Oracle APEX para recuperar, modificar y administrar información de manera segura y eficiente ") -> Implementa consultas SQL usando gestores de bases de datos relacionales como Oracle APEX para recuperar, modificar y administrar información de manera segura y eficiente | D9: =IFERROR(__xludf.DUMMYFUNCTION("""COMPUTED_VALUE"""),1.0) -> 1 | E9: =IFERROR(__xludf.DUMMYFUNCTION("""COMPUTED_VALUE"""),"Introducción a base de datos relacionales") -> Introducción a base de datos relacionales | F9: =IFERROR(__xludf.DUMMYFUNCTION("""COMPUTED_VALUE"""),"Anatomia de una sentencia SQL") -> Anatomia de una sentencia SQL | G9: =IFERROR(__xludf.DUMMYFUNCTION("""COMPUTED_VALUE"""),"Julio") -> Julio | H9: =IFERROR(__xludf.DUMMYFUNCTION("""COMPUTED_VALUE"""),1.0) -> 1
B10: =IFERROR(__xludf.DUMMYFUNCTION("""COMPUTED_VALUE"""),4.0) -> 4 | C10: =IFERROR(__xludf.DUMMYFUNCTION("""COMPUTED_VALUE"""),"Diseña modelos de bases de datos utilizando diagramas entidad-relación y normalización para garantizar integridad, consistencia y eficiencia en el acceso a los datos ") -> Diseña modelos de bases de datos utilizando diagramas entidad-relación y normalización para garantizar integridad, consistencia y eficiencia en el acceso a los datos | D10: =IFERROR(__xludf.DUMMYFUNCTION("""COMPUTED_VALUE"""),2.0) -> 2 | E10: =IFERROR(__xludf.DUMMYFUNCTION("""COMPUTED_VALUE"""),"Modelo Entidad-Relación") -> Modelo Entidad-Relación | F10: =IFERROR(__xludf.DUMMYFUNCTION("""COMPUTED_VALUE"""),"Modelo Conceptual") -> Modelo Conceptual | G10: =IFERROR(__xludf.DUMMYFUNCTION("""COMPUTED_VALUE"""),"Julio") -> Julio | H10: =IFERROR(__xludf.DUMMYFUNCTION("""COMPUTED_VALUE"""),2.0) -> 2
B11: =IFERROR(__xludf.DUMMYFUNCTION("""COMPUTED_VALUE"""),5.0) -> 5 | C11: =IFERROR(__xludf.DUMMYFUNCTION("""COMPUTED_VALUE"""),"Diseña modelos de bases de datos utilizando diagramas entidad-relación y normalización para garantizar integridad, consistencia y eficiencia en el acceso a los datos ") -> Diseña modelos de bases de datos utilizando diagramas entidad-relación y normalización para garantizar integridad, consistencia y eficiencia en el acceso a los datos | D11: =IFERROR(__xludf.DUMMYFUNCTION("""COMPUTED_VALUE"""),2.0) -> 2 | E11: =IFERROR(__xludf.DUMMYFUNCTION("""COMPUTED_VALUE"""),"Modelo Entidad-Relación") -> Modelo Entidad-Relación | F11: =IFERROR(__xludf.DUMMYFUNCTION("""COMPUTED_VALUE"""),"Modelo Lógico") -> Modelo Lógico | G11: =IFERROR(__xludf.DUMMYFUNCTION("""COMPUTED_VALUE"""),"Julio") -> Julio | H11: =IFERROR(__xludf.DUMMYFUNCTION("""COMPUTED_VALUE"""),2.0) -> 2
B12: =IFERROR(__xludf.DUMMYFUNCTION("""COMPUTED_VALUE"""),6.0) -> 6 | C12: =IFERROR(__xludf.DUMMYFUNCTION("""COMPUTED_VALUE"""),"Diseña modelos de bases de datos utilizando diagramas entidad-relación y normalización para garantizar integridad, consistencia y eficiencia en el acceso a los datos ") -> Diseña modelos de bases de datos utilizando diagramas entidad-relación y normalización para garantizar integridad, consistencia y eficiencia en el acceso a los datos | D12: =IFERROR(__xludf.DUMMYFUNCTION("""COMPUTED_VALUE"""),2.0) -> 2 | E12: =IFERROR(__xludf.DUMMYFUNCTION("""COMPUTED_VALUE"""),"Modelo Entidad-Relación") -> Modelo Entidad-Relación | F12: =IFERROR(__xludf.DUMMYFUNCTION("""COMPUTED_VALUE"""),"Relaciones y sus tipos") -> Relaciones y sus tipos | G12: =IFERROR(__xludf.DUMMYFUNCTION("""COMPUTED_VALUE"""),"Julio") -> Julio | H12: =IFERROR(__xludf.DUMMYFUNCTION("""COMPUTED_VALUE"""),2.0) -> 2
B13: =IFERROR(__xludf.DUMMYFUNCTION("""COMPUTED_VALUE"""),7.0) -> 7 | C13: =IFERROR(__xludf.DUMMYFUNCTION("""COMPUTED_VALUE"""),"Evalúa esquemas de bases de datos aplicando estándares de calidad y seguridad de la información con el fin de optimizar el desempeño y disponibilidad de los datos ") -> Evalúa esquemas de bases de datos aplicando estándares de calidad y seguridad de la información con el fin de optimizar el desempeño y disponibilidad de los datos | D13: =IFERROR(__xludf.DUMMYFUNCTION("""COMPUTED_VALUE"""),2.0) -> 2 | E13: =IFERROR(__xludf.DUMMYFUNCTION("""COMPUTED_VALUE"""),"Modelo Entidad-Relación") -> Modelo Entidad-Relación | F13: =IFERROR(__xludf.DUMMYFUNCTION("""COMPUTED_VALUE"""),"Modelo Físico") -> Modelo Físico | G13: =IFERROR(__xludf.DUMMYFUNCTION("""COMPUTED_VALUE"""),"Julio") -> Julio | H13: =IFERROR(__xludf.DUMMYFUNCTION("""COMPUTED_VALUE"""),2.0) -> 2
B14: =IFERROR(__xludf.DUMMYFUNCTION("""COMPUTED_VALUE"""),8.0) -> 8 | C14: =IFERROR(__xludf.DUMMYFUNCTION("""COMPUTED_VALUE"""),"Evalúa esquemas de bases de datos aplicando estándares de calidad y seguridad de la información con el fin de optimizar el desempeño y disponibilidad de los datos ") -> Evalúa esquemas de bases de datos aplicando estándares de calidad y seguridad de la información con el fin de optimizar el desempeño y disponibilidad de los datos | D14: =IFERROR(__xludf.DUMMYFUNCTION("""COMPUTED_VALUE"""),2.0) -> 2 | E14: =IFERROR(__xludf.DUMMYFUNCTION("""COMPUTED_VALUE"""),"Modelo Entidad-Relación") -> Modelo Entidad-Relación | F14: =IFERROR(__xludf.DUMMYFUNCTION("""COMPUTED_VALUE"""),"ERdish") -> ERdish | G14: =IFERROR(__xludf.DUMMYFUNCTION("""COMPUTED_VALUE"""),"Julio") -> Julio | H14: =IFERROR(__xludf.DUMMYFUNCTION("""COMPUTED_VALUE"""),2.0) -> 2
B15: =IFERROR(__xludf.DUMMYFUNCTION("""COMPUTED_VALUE"""),9.0) -> 9 | C15: =IFERROR(__xludf.DUMMYFUNCTION("""COMPUTED_VALUE"""),"Aplica conceptos de la teoría relacional conviertiendo los requerimientos funciones en tablas normalizadas con el fin de crear sistemas de almacenamiento que garanticen integridad, consistencia y eficiencia de los datos. ") -> Aplica conceptos de la teoría relacional conviertiendo los requerimientos funciones en tablas normalizadas con el fin de crear sistemas de almacenamiento que garanticen integridad, consistencia y eficiencia de los datos. | D15: =IFERROR(__xludf.DUMMYFUNCTION("""COMPUTED_VALUE"""),3.0) -> 3 | E15: =IFERROR(__xludf.DUMMYFUNCTION("""COMPUTED_VALUE"""),"Normalización Parte 1") -> Normalización Parte 1 | F15: =IFERROR(__xludf.DUMMYFUNCTION("""COMPUTED_VALUE"""),"Primera Forma Normal") -> Primera Forma Normal | G15: =IFERROR(__xludf.DUMMYFUNCTION("""COMPUTED_VALUE"""),"Agosto") -> Agosto | H15: =IFERROR(__xludf.DUMMYFUNCTION("""COMPUTED_VALUE"""),3.0) -> 3
B16: =IFERROR(__xludf.DUMMYFUNCTION("""COMPUTED_VALUE"""),10.0) -> 10 | C16: =IFERROR(__xludf.DUMMYFUNCTION("""COMPUTED_VALUE"""),"Diseña modelos de bases de datos utilizando diagramas entidad-relación y normalización para garantizar integridad, consistencia y eficiencia en el acceso a los datos ") -> Diseña modelos de bases de datos utilizando diagramas entidad-relación y normalización para garantizar integridad, consistencia y eficiencia en el acceso a los datos | D16: =IFERROR(__xludf.DUMMYFUNCTION("""COMPUTED_VALUE"""),3.0) -> 3 | E16: =IFERROR(__xludf.DUMMYFUNCTION("""COMPUTED_VALUE"""),"Normalización Parte 1") -> Normalización Parte 1 | F16: =IFERROR(__xludf.DUMMYFUNCTION("""COMPUTED_VALUE"""),"Segunda Forma Normal") -> Segunda Forma Normal | G16: =IFERROR(__xludf.DUMMYFUNCTION("""COMPUTED_VALUE"""),"Agosto") -> Agosto | H16: =IFERROR(__xludf.DUMMYFUNCTION("""COMPUTED_VALUE"""),3.0) -> 3
B17: =IFERROR(__xludf.DUMMYFUNCTION("""COMPUTED_VALUE"""),11.0) -> 11 | C17: =IFERROR(__xludf.DUMMYFUNCTION("""COMPUTED_VALUE"""),"Diseña modelos de bases de datos utilizando diagramas entidad-relación y normalización para garantizar integridad, consistencia y eficiencia en el acceso a los datos ") -> Diseña modelos de bases de datos utilizando diagramas entidad-relación y normalización para garantizar integridad, consistencia y eficiencia en el acceso a los datos | D17: =IFERROR(__xludf.DUMMYFUNCTION("""COMPUTED_VALUE"""),3.0) -> 3 | E17: =IFERROR(__xludf.DUMMYFUNCTION("""COMPUTED_VALUE"""),"Normalización Parte 1") -> Normalización Parte 1 | F17: =IFERROR(__xludf.DUMMYFUNCTION("""COMPUTED_VALUE"""),"Tipos de Datos") -> Tipos de Datos | G17: =IFERROR(__xludf.DUMMYFUNCTION("""COMPUTED_VALUE"""),"Agosto") -> Agosto | H17: =IFERROR(__xludf.DUMMYFUNCTION("""COMPUTED_VALUE"""),3.0) -> 3
